Workbook

Sheet Treasury Dashboard FNL
B4: TREASURY DASHBOARD- | K4: 15th August 2026
L6: ( All Amount in Million QAR) | AJ6: Total Funds | AK6: Amount
AJ7: Cash in Bank | AK7: =#REF! -> #REF!
B8: FUNDS POSITION
C9: BANK BALANCE IN QAR CURRENCY
B26: CASH FLOW PROJECTION FOR THE PERIOD AUGUST 2026 TO OCTOBER 2026 EXCLUDING MURABAHA PAYMENTS
H27: Surplus / (Deficit) funds | N27: 1. This section will be updated manually. 2. Major supplier payments through LC during next 3 months included in the cash flow are as follows: Aug 2026 QAR. XX Mn towards wheat LC (QFM) QAR. XX Mn towards barley LC (QFT). Sep 2026 QAR. XX Mn towards wheat LC (QFM) QAR. XX Mn towards barley LC (QFT). Oct 2026 QAR. XX Mn towards wheat LC (QFM) QAR. XX Mn towards Barley LC (QFT). | R27: This N column will be manually updated.
B41: WORKING CAPITAL FINANCE LIMITS AND UTILISATION
N42: LC & Murabaha limits are sub limits of total facility limit
AA47: 363
AA48: 548
AB56: =710+363+548 -> 1621
B59: REGION WISE FACILITY UTILISATION SUMMARY
B76: SHORT TERM LOAN - REPAYMENT SCHEDULE & CURRENT OUTSTANDING
B90: TERM LOAN POSITION FOR THE YEAR
N103: LONG TERM LOAN REPAYMENT
N104: This section will be manually updated. 1.MAI # 1 : Quarterly installments payable ,next installment due in Sep-2026. QAR XX mn plus profit per installment. 2.UBS # 1 Long Term Loan next installment due in Nov-2026. QAR XX mn plus profit per installment 3.DUK # 1 long-term loan installment is due on the 12th of every month. QAR XX mn plus profit per installment 4.MAI # 2 :New loan availed on 15-Jan-2026 ,1st installment will be due in Oct-2026. QAR XX mn plus profit per installment. 5.DUK # 2 :New loan availed on 24-Jun-2026 ,1st installment will be due in Sep-2027 after the grace period. | R104: This N column will be manually updated.
B135: Note: 1.This section will be manually updated. | R135: This Note section will be manually updated.
B148: Note :- As per the Management instruction , to increase the short term debt upto QR 510 Mn & repay the long term loan . This strategy needs to be revisited under the current blockade situation . Another option thought off was to find other bank to create additonal facility in OMAN & Kuwait . Bank from OMAN - Maisarah has quoted 5.51 % p.a for 180 days tenure murabaha.However working with foreign bank is not feasible under the current blocade scenario , as local bankers resist in making fund transfer to foreign banks.
B153: Values are in QAR MN
B157: SHORT TERM LOAN VS LONG TERM LOANS
B177: LIQUID ASSETS TO DEBT
B178: LIQUID ASSETS ON HISTORICAL COST | J178: LIQUID ASSETS ON MARKET VALUES
B213: INVESTMENTS IN SHARE MARKET
B223: Values are in Qatari Riyal Millions . Foreign Market Share Price is considered as per Investment Department and Local Shares Market Price is considered as per QE
B227: INVESTMENT IN FIXED DEPOSITS
B228: 1.Total Fixed Deposit
C229: FROM | E229: TO | G229: Renewal (R) / Placement (P) | I229: Maturity | K229: Rate ( In % ) | L229: Amt
C230: (A) Fixed Deposit with Barwa Bank
C234: (A) Fixed Deposit with Barwa Bank
C235: 43629 | E235: =+C235+7 -> 43636 | G235: (N) | I235: 1 Week | K235: 2.5
C236: (B) Fixed Deposit with Qatar First bank
C237: 43615 | E237: 43707 | G237: (N) | I237: 3 Months | K237: 4.25 | L237: 0
C238: (C) Fixed Deposit with Barwa Bank
C240: Total | K240: =SUM(L231:L239) -> 0
B244: INFORMATION ON DOLLAR AVAILABILITY
C246: PARTICULARS | G246: INFORMATION / ANALYSIS
C247: Scenario prior to blockade | G247: Availability - Sufficient , Exchange rate within Qatar - 3.6416 to 3.6418 , Exchange rate outside doha - 3.6416 to 3,6423 . Reason :- Regular flow dollar from blockade countries in the form of deposits , loans , investment etc
C248: During the initial month of blockade | G248: Availability -Temporary shortage , However no issue for Zad to get dollar , Exchange rate within Qatar - 3.6416 to 3.6418 , Exchange rate outside qatar - 3.6475 to 3.6480 . Reason :- Withdrawal of deposit , early loan repayment , no new deposit or investment etc .
C249: Current scenario | G249: Availability -Insufficent , Dollar is made available by QCB in regulated manner , bankers has to apply for dollar quantity to QCB with all details , subsequently on approval dollar , is made available Exchange rate within Qatar - 3.65 , Exchange rate outside qatar - 3.6475 to 3.6480 . Reason :- Withdrawal of deposit , early loan repayment , no new deposit or investment etc . As per one of the article qatari bank has cut dollar sale to foreiqn lenders & from our routine transaction & enquiry it has been noticed dollar are not available with mashreq bank qatar , however dollar are available with Al Rayan @ 3.65
...

Sheet 1. Funds position
A1: Guideline:
A2: The below information is extracted from Bank statements. & filled up in the blue colored cells.
A3: Data updation timeline: Previous day bank statement data updated every working day by 9 am.
B7: FUNDS POSITION
A9: =B9 -> Doha Bank | B9: Doha Bank
A10: =A9 -> Doha Bank | B10: ZAD | C10: 0222-0168686-001-0010-000 | D10: CUR Current | F10: QAR | G10: =+'ZAD-0222-0168686-001-0010-000'!B2 -> 2877749
A12: Dukhan Bank | B12: Dukhan Bank
A13: Dukhan Bank | B13: Company Name | C13: Account No | D13: Account Type | E13: Branch Name | F13: Currency | G13: Amount
A14: Dukhan Bank | B14: ASP | C14: 100001845559 | D14: CUR Current | E14: MAIN BRANCH | F14: QAR | G14: =+'ASP-100001845559'!B2 -> 26451
A15: Dukhan Bank | B15: ACC | C15: 100000279773 | D15: CUR Current | E15: MAIN BRANCH | F15: QAR | G15: =+'ACC-100000279773'!B2 -> 16031
A16: Dukhan Bank | B16: ACC | C16: 100000827646 | D16: CUR Current | E16: MAIN BRANCH | F16: QAR | G16: =+'ACC-100000827646'!B2 -> 6484
A17: Dukhan Bank | B17: ALC | C17: 100000841415 | D17: CUR Current | E17: MAIN BRANCH | F17: QAR | G17: =+'ALC-100000841415'!B2 -> 51254
A18: Dukhan Bank | B18: ARZAK | C18: 100000819104 | D18: CUR Current | E18: MAIN BRANCH | F18: QAR | G18: =+'AMC-100000819104'!B2 -> 16388
A19: Dukhan Bank | B19: GUC | C19: 100000824416 | D19: CUR Current | E19: MAIN BRANCH | F19: QAR | G19: =+'GUC-100000824416'!B2 -> 23549
A20: Dukhan Bank | B20: NFC | C20: 100000792904 | D20: CUR Current | E20: MAIN BRANCH | F20: QAR | G20: =+'NFC-100000792904'!B2 -> 31880
A21: Dukhan Bank | B21: QFT | C21: 100000185812 | D21: CUR Current | E21: MAIN BRANCH | F21: QAR | G21: =+'QFT-100000185812'!B2 -> 8051
A22: Dukhan Bank | B22: QFM | C22: 100000832880 | D22: CUR Current | E22: MAIN BRANCH | F22: QAR | G22: =+'QFM-100000832880'!B2 -> 25182
A23: Dukhan Bank | B23: QFI | C23: 100000780301 | D23: CUR Current | E23: MAIN BRANCH | F23: QAR | G23: =+'QFI-100000780301'!B2 -> 90531
A24: Dukhan Bank | B24: QFI | C24: 100000832877 | D24: CUR Current | E24: MAIN BRANCH | F24: QAR | G24: =+'QFI-100000832877'!B2 -> 45854
A25: Dukhan Bank | B25: USB | C25: 100000792506 | D25: CUR Current | E25: MAIN BRANCH | F25: QAR | G25: =+'USB-100000792506'!B2 -> 60221.27
A26: Dukhan Bank | B26: UNB | C26: 100001798347 | D26: CUR Current | E26: MAIN BRANCH | F26: QAR | G26: =+'UNB-100001798347'!B2 -> 73391
A27: Dukhan Bank | B27: UNB | C27: 100001833574 | D27: CUR Current | E27: MAIN BRANCH | F27: QAR | G27: 50000 | H27: NO TRANSACTION FROM FEB-2026
A28: Dukhan Bank | B28: AUTO MEDIA | C28: 100002593758 | D28: CUR Current | E28: MAIN BRANCH | F28: QAR | G28: =+'AUTO M-100002593758'!B2 -> 20100
A29: Dukhan Bank | B29: ZAD | C29: 100000182792 | D29: CUR Current | E29: MAIN BRANCH | F29: QAR | G29: =+'ZAD-100000182792'!B2 -> 58917
A30: Dukhan Bank | B30: ZAD | C30: 100000763315 | D30: CMG CASH MARGIN | E30: MAIN BRANCH | F30: QAR | G30: 180000 | H30: NO TRANSACTION FROM FEB-2026
A31: Dukhan Bank | B31: ZAD CALL ACCOUNT | C31: 200001066225 | D31: CALL ACCOUNT | E31: MAIN BRANCH | F31: QAR | G31: =+'ZAD-200001066225'!B2 -> 31866
A32: Dukhan Bank | B32: ZAD | C32: 200000597452 | D32: CASHLINE | E32: MAIN BRANCH | F32: QAR | G32: =+'ZAD-200000597452'!B2 -> 261842
A34: QIB | B34: ZAD | C34: 0111051730026 | G34: =+'ZAD-0111051730026'!B2 -> 34557
A36: Al Rayan | B36: ZAD | C36: 0003177700001 | D36: Currrent | F36: QAR | G36: =+'ZAD-0003177700001'!B2 -> 408426
A37: Al Rayan | B37: ACC | C37: 0003-104174-001 | D37: Currrent | F37: QAR | G37: 20000
A39: Mashreq | B39: Mashreq
A40: Mashreq | B40: GUC | C40: 20490009938 | F40: QAR | G40: 10000
A41: Mashreq | B41: ZAD | C41: 29000000712 | F41: QAR | G41: =+'ZAD-29000000712'!B2 -> 9845
A42: Mashreq | B42: ZAD | C42: 11941000032 | F42: QAR | G42: =+'ZAD-11941000032'!B2 -> 638733
A44: Dukhan Bank | B44: ARZAK | C44: 100001872603 | D44: USD | E44: =+'AMC-100001872603'!B2 -> 14215 | F44: 3.65 | G44: =E44*F44 -> 51884.75
A45: Dukhan Bank | B45: ACC | C45: 100001870650 | D45: USD | E45: =+'ACC-100001870650'!B2 -> 5624 | F45: 3.65 | G45: =E45*F45 -> 20527.6
A46: Dukhan Bank | B46: QFT | C46: 100001870728 | D46: USD | E46: =+'QFT-100001870728'!B2 -> 76205 | F46: 3.65 | G46: =E46*F46 -> 278148.25
A47: Dukhan Bank | B47: QFI | C47: 100001870676 | D47: USD | E47: 0 | F47: 3.65 | G47: 0 | H47: NO TRANSACTION FROM FEB-2026
A48: Dukhan Bank | B48: QFM | C48: 100001870618 | D48: USD | E48: =+'QFM-100001870618'!B2 -> 54684.56 | F48: 3.65 | G48: =E48*F48 -> 199598.64
A49: Dukhan Bank | B49: USB | C49: 100001870634 | D49: USD | E49: =+'USB-100001870634'!B2 -> 21046 | F49: 3.65 | G49: =E49*F49 -> 76817.9
...

Sheet 2. Cash flow
A1: Guideline:
A2: The below information is extracted from Cash flow projection file & the net amounts will be filled up in the blue colored cells.
A3: Data updation timeline: Reviewed & updated every working day by 9 am.
B6: CASH FLOW PROJECTION FOR THE PERIOD AUGUST 2026 TO OCTOBER 2026 EXCLUDING MURABAHA PAYMENTS
B8: Month | C8: Cash Inflow | D8: Cash Outflow | E8: Net balance | F8: Surplus / (Deficit)
B9: Aug | C9: 100 | D9: 90 | E9: ='2. Cash flow'!C9-'2. Cash flow'!D9 -> 10 | F9: =+IF(E9>0,"Surplus", "Deficit") -> Surplus
B10: Sep | C10: =+C9+20 -> 120 | D10: 120 | E10: ='2. Cash flow'!C10-'2. Cash flow'!D10 -> 0 | F10: =+IF(E10>0,"Surplus", "Deficit") -> Deficit
B11: Oct | C11: =+C10+20 -> 140 | D11: 145 | E11: ='2. Cash flow'!C11-'2. Cash flow'!D11 -> -5 | F11: =+IF(E11>0,"Surplus", "Deficit") -> Deficit
B12: Total | C12: =SUM(C9:C11) -> 360 | D12: =SUM(D9:D11) -> 355 | E12: =SUM(E9:E11) -> 5

Sheet 3. Working capital
A1: Guideline:
A2: The below information is extracted from Loan summary document.
A3: Blue fields only to be updated
A4: Data updation timeline: Murabaha utilization & payments will be updated on daily basis.
A5: Utilization of LC and Bonds & BGs will be updated on weekly basis.
B7: WORKING CAPITAL FINANCE LIMITS AND UTILISATION
E9: Bonds & Guarantee | F9: Total | G9: USD
C10: LC | D10: Murabaha | G10: =F10/3.65 -> 0
B11: Sanctioned Limit | G11: =F11/3.65 -> 0
B12: DUK | C12: 250 | D12: 10 | E12: 50 | F12: =C12+E12 -> 300 | G12: =F12/3.65 -> 82.191781
B13: MAI | C13: 200 | D13: 75 | E13: 10 | F13: =C13+E13 -> 210 | G13: =F13/3.65 -> 57.534247
B14: UBS | C14: 0 | D14: 15 | E14: 0 | F14: =C14+E14 -> 0 | G14: =F14/3.65 -> 0
B15: QIB | C15: 50 | D15: 30 | E15: 20 | F15: =C15+E15 -> 70 | G15: =F15/3.65 -> 19.178082
B16: Al Rayan | C16: 125 | D16: 2 | E16: 10 | F16: =C16+E16 -> 135 | G16: =F16/3.65 -> 36.986301
B17: Total | C17: =SUM(C12:C16) -> 625 | D17: =SUM(D12:D16) -> 132 | E17: =SUM(E12:E16) -> 90 | F17: =SUM(F12:F16) -> 715 | G17: =SUM(G12:G16) -> 195.89041
C20: Working Capital Limits - Bank Wise Summary
D21: LC | E21: Murabaha | F21: B&G
C22: QIB | D22: 4.3365e-05 | E22: 0 | F22: 4
C23: MAI | D23: 0 | E23: 70 | F23: 0
C24: Al Rayan | D24: 15 | E24: 2 | F24: 2
C25: Duk | D25: 100 | E25: 10 | F25: 15
C26: UBS | D26: 0 | E26: 15 | F26: 0
C27: DBQ | D27: 0 | E27: 0 | F27: 0
D28: =SUM(D22:D27) -> 115.00004 | E28: =SUM(E22:E27) -> 97 | F28: =SUM(F22:F27) -> 21
A30: 1 | B30: Working Capital Limits - Bank Wise
B32: Qatar Islamic Bank | C32: Sanctioned | D32: Utilised | E32: Under Process | F32: Utilisation %
B33: LC | C33: 50 | D33: ='3. Working capital'!D22 -> 4.3365e-05 | E33: 0 | F33: =IFERROR(SUM(D33:E33)/C33,0) -> 8.673e-07
B34: Murabaha | C34: 40 | D34: ='3. Working capital'!E22 -> 0 | E34: 0 | F34: =IFERROR(SUM(D34:E34)/C34,0) -> 0
B35: Bonds & Guarantees | C35: 10 | D35: 3.715586 | E35: 0 | F35: =IFERROR(SUM(D35:E35)/C35,0) -> 0.3715586
B36: Total Limit | C36: =SUM(C34:C35) -> 50 | D36: =SUM(D33:D35) -> 3.7156294 | E36: =SUM(E33:E34) -> 0 | F36: =IFERROR(SUM(D36:E36)/C36,0) -> 0.074312587
F37: =IFERROR(SUM(D37:E37)/C37,0) -> 0
B38: Mashreq Bank | C38: Sanctioned | D38: Utilised | E38: Under Process | F38: Utilisation %
B41: LC | C41: ='3. Working capital'!C13 -> 200 | D41: ='3. Working capital'!D23 -> 0 | F41: =IFERROR(SUM(D41:E41)/C41,0) -> 0
B42: Murabaha | C42: =D13 -> 75 | D42: ='3. Working capital'!E23 -> 70 | F42: =IFERROR(SUM(D42:E42)/C42,0) -> 0.93333333
B43: Bonds & Guarantees | C43: ='3. Working capital'!E13 -> 10 | D43: ='3. Working capital'!F23 -> 0 | F43: =IFERROR(SUM(D43:E43)/C43,0) -> 0
B44: Total Limit | C44: =SUM(C42:C43) -> 85 | D44: =SUM(D41:D43) -> 70 | E44: =SUM(E41:E43) -> 0 | F44: =IFERROR(SUM(D44:E44)/C44,0) -> 0.82352941
B46: Al Rayan | C46: Sanctioned | D46: Utilised | E46: Under Process | F46: Utilisation %
B47: LC | C47: ='3. Working capital'!C16 -> 125 | D47: ='3. Working capital'!D24 -> 15 | F47: =IFERROR(SUM(D47:E47)/C47,0) -> 0.12
B48: Murabaha | C48: ='3. Working capital'!C16 -> 125 | D48: ='3. Working capital'!E24 -> 2 | F48: =IFERROR(SUM(D48:E48)/C48,0) -> 0.016
B49: Bonds & Guarantees | C49: ='3. Working capital'!E15 -> 20 | D49: ='3. Working capital'!F24 -> 2 | F49: =IFERROR(SUM(D49:E49)/C49,0) -> 0.1
...

Sheet 4. Loan
B1: Guideline:
B2: The below information is extracted from Loan summary document & loan repayment schedule.
B3: =+'3. Working capital'!A3 -> Blue fields only to be updated
B4: Data updation timeline: Reviewed & updated every working day by 9 am.
B8: SHORT TERM LOAN - REPAYMENT SCHEDULE & CURRENT OUTSTANDING
C9: Repayment
B10: Bank | C10: 46265 | D10: 46295 | E10: 46326 | F10: Total O/S
B11: QIB | C11: 0 | D11: 0 | E11: 0 | F11: 0 | G11: QIB @ 4%
B12: Mashreq | C12: 0 | D12: 0 | E12: 0 | F12: =+'3. Working capital'!D76 -> 70 | G12: Mashreq @ 4%
B13: UBS | C13: 2 | D13: 0 | E13: 0 | F13: 25 | G13: UBS @ 4%
B14: Dukhan | C14: 2 | D14: 2 | E14: 2 | F14: 20 | G14: Dukhan @ 4%
B15: Al Rayan | C15: 0 | D15: 0 | E15: 0 | F15: 10 | G15: Al Rayan @ 4%
B16: Total | C16: =SUM(C11:C15) -> 4 | D16: =SUM(D11:D15) -> 2 | E16: =SUM(E11:E15) -> 2 | F16: =SUM(F11:F15) -> 125 | G16: Total
B19: Details of Long term loans (in QAR millions) | I19: Paid till 2025 | J19: Paid during YTD 2026 | K19: Balance outstanding | L19: Repayment schedule of balance outstanding
B20: Bank | C20: Loan description | D20: Loan amount | E20: Tenure | F20: Start date | G20: End date | H20: Installment frequency | L20: 2026 | M20: =+L20+1 -> 2027 | N20: =+M20+1 -> 2028 | O20: =+N20+1 -> 2029 | P20: =+O20+1 -> 2030 | Q20: =+P20+1 -> 2031 | R20: =+Q20+1 -> 2032 | S20: =+R20+1 -> 2033 | T20: =+S20+1 -> 2034 | U20: 2035-2038
B21: Mashreq Al Islami (MAI) | C21: MAI # 1 | D21: 100 | E21: 8 years | F21: 44383 | G21: 47263 | H21: Quarterly | I21: 50 | J21: 8 | K21: =+D21-I21-J21 -> 42 | L21: 5 | M21: 10 | N21: =+M21 -> 10 | O21: 17 | P21: 0 | Q21: 0 | R21: 0 | S21: 0 | T21: 0 | U21: 0 | V21: =K21-SUM(L21:U21) -> 0
B22: UBS | C22: UBS # 1 | D22: =+D21+25 -> 125 | E22: 5 years | F22: 44888 | G22: 46703 | H22: Half yearly | I22: 50 | J22: 15 | K22: =+D22-I22-J22 -> 60 | L22: 26.1 | M22: 33.9 | N22: 0 | O22: 0 | P22: 0 | Q22: 0 | R22: 0 | S22: 0 | T22: 0 | U22: 0 | V22: =K22-SUM(L22:U22) -> 0
B23: Dukhan bank (DUK) | C23: DUK # 1 | D23: =+D22+25 -> 150 | E23: 8 years | F23: 45029 | G23: 47951 | H23: Monthly | I23: 30 | J23: 3 | K23: =+D23-I23-J23 -> 117 | L23: 7 | M23: 20 | N23: =+M23 -> 20 | O23: =+N23 -> 20 | P23: =+O23 -> 20 | Q23: 30 | R23: 0 | S23: 0 | T23: 0 | U23: 0 | V23: =K23-SUM(L23:U23) -> 0
B24: Mashreq Al Islami (MAI) | C24: MAI # 2 | D24: =+D23+25 -> 175 | E24: 7 years | F24: 46037 | G24: 12067 | H24: Quarterly | I24: 0 | J24: 0 | K24: =+D24-I24-J24 -> 175 | L24: =6.17*2 -> 12.34 | M24: 20 | N24: =+M24 -> 20 | O24: =+N24 -> 20 | P24: =+O24 -> 20 | Q24: =+P24 -> 20 | R24: =+Q24 -> 20 | S24: 42.7 | T24: 0 | U24: 0 | V24: =K24-SUM(L24:U24) -> -0.04
B25: Dukhan bank (DUK) | C25: DUK # 2 | D25: 100 | E25: 8 years | F25: 46197 | G25: 49119 | H25: Quarterly | I25: 0 | J25: 0 | K25: =+D25-I25-J25 -> 100 | L25: 0 | M25: 5 | N25: 11.5 | O25: =+N25 -> 11.5 | P25: =+O25 -> 11.5 | Q25: =+P25 -> 11.5 | R25: =+Q25 -> 11.5 | S25: =+R25 -> 11.5 | T25: 26 | U25: 0 | V25: =K25-SUM(L25:U25) -> 0
C26: Total | D26: =SUM(D21:D25) -> 650 | I26: =SUM(I21:I25) -> 130 | J26: =SUM(J21:J25) -> 26 | K26: =SUM(K21:K25) -> 494 | L26: =SUM(L21:L25) -> 50.44 | M26: =SUM(M21:M25) -> 88.9 | N26: =SUM(N21:N25) -> 61.5 | O26: =SUM(O21:O25) -> 68.5 | P26: =SUM(P21:P25) -> 51.5 | ... U26: =SUM(U21:U25) -> 0
B27: New long term loan:
B28: Dukhan bank (DUK) | C28: *DUK # 3 | D28: 100 | E28: 12 years | F28: 46252 | G28: =+F28+12*30+5 -> 46617 | H28: Quarterly | I28: 0 | J28: 0 | K28: =+D28-I28-J28 -> 100 | L28: 0 | M28: 0 | N28: 2.05 | O28: 8.2 | P28: =+O28 -> 8.2 | Q28: =+P28 -> 8.2 | R28: =+Q28 -> 8.2 | S28: =+R28 -> 8.2 | T28: =+S28 -> 8.2 | U28: 48.8 | V28: =K28-SUM(L28:U28) -> -0.05
B29: Total including new LTL | D29: =SUM(D26:D28) -> 750 | I29: =SUM(I26:I28) -> 130 | J29: =SUM(J26:J28) -> 26 | K29: =SUM(K26:K28) -> 594 | L29: =SUM(L26:L28) -> 50.44 | M29: =SUM(M26:M28) -> 88.9 | N29: =SUM(N26:N28) -> 63.55 | O29: =SUM(O26:O28) -> 76.7 | P29: =SUM(P26:P28) -> 59.7 | ... U29: =SUM(U26:U28) -> 48.8
E32: Dukhan # 1 | F32: Mashreq Al Islami # 1 | G32: UBS | H32: Mashreq Al Islami # 2 | I32: Dukhan # 2
B33: Q1-2026 | C33: =(E33+F33+G33+H33+I33)/10^6 -> 1.8482822 | E33: =168674.69879518*3 -> 506024.1 | F33: =367741.93548387*3.65 -> 1342258.1
B34: Q2-2026 | C34: =(E34+F34+G34+H34+I34)/10^6 -> 2.1092572 | E34: =168674.69879518*3 -> 506024.1 | F34: =367741.93548387*3.65 -> 1342258.1 | G34: 260975
B35: Q3-2026 (remaining) | C35: =(E35+F35+G35+H35+I35)/10^6 -> 1.8482822 | E35: =168674.69879518*3 -> 506024.1 | F35: =367741.93548387*3.65 -> 1342258.1
B36: Q4-2026 | C36: =(E36+F36+G36+H36+I36)/10^6 -> 4.6277572 | E36: =168674.69879518*3 -> 506024.1 | F36: =367741.93548387*3.65 -> 1342258.1 | G36: =+G34 -> 260975 | H36: =690000*3.65 -> 2518500
B37: Q1-2027 | C37: =(E37+F37+G37+H37+I37)/10^6 -> 4.3667822 | E37: =168674.69879518*3 -> 506024.1 | F37: =367741.93548387*3.65 -> 1342258.1 | H37: =690000*3.65 -> 2518500
B38: Q2-2027 | C38: =(E38+F38+G38+H38+I38)/10^6 -> 4.6277572 | E38: =168674.69879518*3 -> 506024.1 | F38: =367741.93548387*3.65 -> 1342258.1 | G38: =+G36 -> 260975 | H38: =690000*3.65 -> 2518500
B39: Q3-2027 | C39: =(E39+F39+G39+H39+I39)/10^6 -> 5.3519673 | E39: =168674.69879518*3 -> 506024.1 | F39: =367741.93548387*3.65 -> 1342258.1 | H39: =690000*3.65 -> 2518500 | I39: 985185.19
B40: Q4-2027 | C40: =(E40+F40+G40+H40+I40)/10^6 -> 5.6129423 | E40: =168674.69879518*3 -> 506024.1 | F40: =367741.93548387*3.65 -> 1342258.1 | G40: =+G38 -> 260975 | H40: =690000*3.65 -> 2518500 | I40: 985185.19
E41: =SUM(E37:E40)/10^6 -> 2.0240964 | F41: =SUM(F37:F40)/10^6 -> 5.3690323 | G41: =SUM(G37:G40)/10^6 -> 0.52195 | H41: =SUM(H37:H40)/10^6 -> 10.074 | I41: =SUM(I37:I40)/10^6 -> 1.9703704

Sheet 5. Debt & Equity
A1: Guideline:
A2: The below information is extracted from Loan summary document & loan repayment schedule.
A3: =+'4. Loan'!B3 -> Blue fields only to be updated
A4: Data updation timeline: Reviewed & updated every working day by 9 am.
B9: Debt to Equity | C9: 46249
B10: Term Loan vs Short term loan | C10: Outstanding
B11: Short term loan | C11: =+'4. Loan'!F16 -> 125
B12: Long term loan | C12: =+'4. Loan'!K26 -> 494
B13: FD | C13: 0
B14: Liquidity Reserve | C14: =+#REF! -> #REF!
B15: Total | C15: =SUM(C11:C14) -> #REF!
B17: ='5. Debt & Equity'!B24 -> Equity (Book value) | C17: Equity 31-Apr-26 | D17: Dividend paid | E17: FV 31-Mar-26 | F17: FV 10-Aug-26 | G17: FV gain / loss | H17: Avg. EBDA | I17: Equity (Book value)
C18: 800 | D18: 0 | E18: 400 | F18: 500 | G18: =+F18-E18 -> 100 | H18: 50 | I18: =+C18-D18+G18+H18 -> 950
B21: Debt to Equity Ratio
B22: Period Ended on | C22: 45291 | D22: 45657 | E22: 46022 | F22: 46203 | G22: 46234
B23: Debt | C23: 100 | D23: 200 | E23: 300 | F23: 400 | G23: ='5. Debt & Equity'!C15 -> #REF!
B24: Equity (Book value) | C24: 500 | D24: 500 | E24: 600 | F24: 550 | G24: =+'5. Debt & Equity'!I18 -> 950
B25: D/E Ratio (Book value) | C25: =C23/C24 -> 0.2 | D25: =D23/D24 -> 0.4 | E25: =E23/E24 -> 0.5 | F25: =F23/F24 -> 0.72727273 | G25: =G23/G24 -> #REF!
B28: Liquid Assets @ Cost To Debt
B29: Period Ended on | C29: 45291 | D29: 45657 | E29: 46022 | F29: 46203 | G29: 15-Aug-2026
B30: Debt | C30: =+C23 -> 100 | D30: =+D23 -> 200 | E30: =+E23 -> 300 | F30: =+F23 -> 400 | G30: ='5. Debt & Equity'!C15 -> #REF!
B31: Liquid Assets | C31: =SUM(C32:C34) -> 525 | D31: =SUM(D32:D34) -> 510 | E31: =SUM(E32:E34) -> 560 | F31: =SUM(F32:F34) -> 395 | G31: =SUM(G32:G34) -> #REF!
B32: Cash at bank | C32: 35 | D32: 50 | E32: 60 | F32: 45 | G32: =+#REF!/10^6 -> #REF!
B33: Investments at Purchase cost(Shares) | C33: 290 | D33: 260 | E33: 300 | F33: 150 | G33: 200
B34: Investments at Purchase cost(Metal) | C34: 200 | D34: =+C34 -> 200 | E34: =+D34 -> 200 | F34: =+E34 -> 200 | G34: 250
B35: Liquid Assets to Debt ( no of times) Cost basis | C35: =C31/C30 -> 5.25 | D35: =D31/D30 -> 2.55 | E35: =E31/E30 -> 1.8666667 | F35: =F31/F30 -> 0.9875 | G35: =G31/G30 -> #REF!
B38: Liquid Assets @ Mkt Value To Debt
B39: Period Ended on | C39: 45291 | D39: 45657 | E39: 46022 | F39: 46203 | G39: =G29 -> 15-Aug-2026
B40: Debt | C40: 525 | D40: 525 | E40: 682.4 | F40: 1173.9 | G40: =G30 -> #REF!
B41: Liquid Assets | C41: =SUM(C42:C44) -> 549.5 | D41: =SUM(D42:D44) -> 533 | E41: =SUM(E42:E44) -> 585 | F41: =SUM(F42:F44) -> 412.5 | G41: =SUM(G42:G44) -> #REF!
B42: Cash at bank | C42: =+C32 -> 35 | D42: =+D32 -> 50 | E42: =+E32 -> 60 | F42: =+F32 -> 45 | G42: =G32 -> #REF!
B43: Market Value of Investments (Shares) | C43: =+C33*105% -> 304.5 | D43: =+D33*105% -> 273 | E43: =+E33*105% -> 315 | F43: =+F33*105% -> 157.5 | G43: =F18 -> 500
B44: Market Value of Investments (Metal) | C44: =+C34*105% -> 210 | D44: =+D34*105% -> 210 | E44: =+E34*105% -> 210 | F44: =+F34*105% -> 210 | G44: =K47 -> 7.582927 | I44: Gold | J44: Silver
B45: Liquid Assets to Debt ( no of times) Mkt Values | C45: =C41/C40 -> 1.0466667 | D45: =D41/D40 -> 1.0152381 | E45: =E41/E40 -> 0.85726846 | F45: =F41/F40 -> 0.35139279 | G45: =G41/G40 -> #REF! | H45: Qty Oz | I45: 375 | J45: 6893
H46: Mkt rate | I46: 4357.63 | J46: 64.74
H47: Amount in QAR | I47: =(I45*I46*3.645)/10^6 -> 5.9563355 | J47: =(J45*J46*3.645)/10^6 -> 1.6265915 | K47: =SUM(I47:J47) -> 7.582927

Sheet 6. Loan movement
B3: Loan Summary | G3: Amount in QR Million
B4: Projected loan movement schedule
B5: Short Term Loans | C5: Loan outstanding as on 01-Aug-26 | D5: 46235 | G5: 46266 | J5: 46296 | M5: 46327
D6: Payment | E6: New Loan | F6: Balance | G6: Payment | H6: New Loan | I6: Balance | J6: Payment | K6: New Loan | L6: Balance | M6: Payment | N6: New Loan | O6: Balance
B7: Dukhan Bank (Loan + CL) | C7: =+'3. Working capital'!E25 -> 10 | D7: -10 | F7: =C7+E7+D7 -> 0 | G7: -10 | I7: =F7+G7+H7 -> -10 | J7: 0 | K7: 0 | L7: =I7+J7+K7 -> -10 | M7: 0 | N7: 0 | O7: =L7+M7+N7 -> -10
B8: Mashreq Al Islami | C8: =+'4. Loan'!F12 -> 70 | D8: -20 | E8: 0 | F8: =C8+E8+D8 -> 50 | G8: -20 | I8: =F8+G8+H8 -> 30 | J8: -45 | K8: 44 | L8: =I8+J8+K8 -> 29 | M8: -54 | N8: 25 | O8: =L8+M8+N8 -> 0
B9: UBS | C9: =+'4. Loan'!F13 -> 25 | D9: -25 | E9: 28 | F9: =C9+E9+D9 -> 28 | G9: -28 | I9: =F9+G9+H9 -> 0 | J9: 0 | K9: 0 | L9: =I9+J9+K9 -> 0 | M9: 0 | N9: 0 | O9: =L9+M9+N9 -> 0
B10: Al Rayyan | C10: =+'4. Loan'!F15 -> 10 | D10: 0 | F10: =C10+E10+D10 -> 10 | G10: -10 | I10: =F10+G10+H10 -> 0 | J10: 0 | L10: =I10+J10+K10 -> 0 | M10: 0 | N10: 0 | O10: =L10+M10+N10 -> 0
B11: QDB | C11: 0 | E11: 0 | F11: =C11+E11+D11 -> 0 | G11: 0 | I11: =F11+G11+H11 -> 0 | J11: 0 | L11: =I11+J11+K11 -> 0 | M11: 0 | O11: =L11+M11+N11 -> 0
B12: Total-A | C12: =SUM(C7:C11) -> 115 | D12: =SUM(D7:D11) -> -55 | E12: =SUM(E7:E11) -> 28 | F12: =SUM(F7:F11) -> 88 | G12: =SUM(G7:G11) -> -68 | H12: =SUM(H7:H11) -> 0 | I12: =SUM(I7:I11) -> 20 | J12: =SUM(J7:J11) -> -45 | ... O12: =SUM(O7:O11) -> -10
B13: Long Term Loans
B14: Mashreq Al Islami # 1 | C14: =+'4. Loan'!K21 -> 42 | D14: 0 | E14: 0 | F14: =C14+D14+E14 -> 42 | G14: -4.9922583 | H14: 0 | I14: =F14+G14+H14 -> 37.007742 | J14: 0 | K14: 0 | L14: =I14+J14+K14 -> 37.007742 | M14: 0 | N14: 0 | O14: =L14+M14+N14 -> 37.007742
B15: Mashreq Al Islami # 2 | C15: =+'4. Loan'!K24 -> 175 | D15: 0 | E15: 0 | F15: =C15+D15+E15 -> 175 | G15: 0 | H15: 0 | I15: =F15+G15+H15 -> 175 | J15: -6.1758 | K15: 0 | L15: =I15+J15+K15 -> 168.8242 | M15: 0 | N15: 0 | O15: =L15+M15+N15 -> 168.8242
B16: UBS | C16: =+'4. Loan'!K22 -> 60 | D16: 0 | E16: 0 | F16: =C16+E16+D16 -> 60 | G16: 0 | H16: 0 | I16: =F16+G16+H16 -> 60 | J16: 0 | K16: 0 | L16: =I16+J16+K16 -> 60 | M16: 0 | N16: 0 | O16: =L16+M16+N16 -> 60
B17: Dukhan Bank # 1 | C17: =+'4. Loan'!K23 -> 117 | D17: -2.1686747 | E17: 0 | F17: =C17+E17+D17 -> 114.83133 | G17: -2.1686747 | H17: 0 | I17: =F17+G17+H17 -> 112.66265 | J17: -2.1686747 | K17: 0 | L17: =I17+J17+K17 -> 110.49398 | M17: -2.1686747 | N17: 0 | O17: =L17+M17+N17 -> 108.3253
B18: Commercial Bank | C18: 0 | D18: 0 | F18: =C18+E18+D18 -> 0 | G18: 0 | I18: =F18+G18+H18 -> 0 | J18: 0 | K18: 0 | L18: =I18+J18+K18 -> 0 | M18: 0 | N18: 0 | O18: =L18+M18+N18 -> 0
B19: Dukhan Bank # 2 | C19: =+'4. Loan'!K25 -> 100 | D19: 0 | E19: 0 | F19: =C19+E19+D19 -> 100 | G19: 0 | H19: 0 | I19: =F19+G19+H19 -> 100 | J19: 0 | K19: 0 | L19: =I19+J19+K19 -> 100 | M19: 0 | N19: 0 | O19: =L19+M19+N19 -> 100
B20: Dukhan Bank # 3 | C20: 0 | D20: 0 | E20: =+'4. Loan'!D28 -> 100 | F20: =C20+E20+D20 -> 100 | G20: 0 | H20: 0 | I20: =F20+G20+H20 -> 100 | J20: 0 | K20: 0 | L20: =I20+J20+K20 -> 100 | M20: 0 | N20: 0 | O20: =L20+M20+N20 -> 100
B21: Total-B | C21: =SUM(C14:C20) -> 494 | D21: =SUM(D14:D20) -> -2.1686747 | E21: =SUM(E14:E20) -> 100 | F21: =SUM(F14:F20) -> 591.83133 | G21: =SUM(G14:G20) -> -7.160933 | H21: =SUM(H14:H20) -> 0 | I21: =SUM(I14:I20) -> 584.67039 | J21: =SUM(J14:J20) -> -8.3444747 | ... O21: =SUM(O14:O20) -> 574.15724
B22: Total Loans (A + B) | C22: =C21+C12 -> 609 | D22: =D21+D12 -> -57.168675 | E22: =E21+E12 -> 128 | F22: =F21+F12 -> 679.83133 | G22: =G21+G12 -> -75.160933 | H22: =H21+H12 -> 0 | I22: =I21+I12 -> 604.67039 | J22: =J21+J12 -> -53.344475 | ... O22: =O21+O12 -> 564.15724
B23: Fixed Deposit (Liquidity Reserve) | C23: 0 | D23: 0 | E23: 0 | F23: =C23+E23+D23 -> 0 | L23: =I23+J23+K23 -> 0 | O23: =L23+M23+N23 -> 0
B24: Liquidity Reserve - HSBC -FD 3M | C24: -10 | D24: 0 | E24: 0 | F24: =C24+E24+D24 -> -10 | G24: 0 | H24: =SUM(H23:H23) -> 0 | I24: =F24+H24+G24 -> -10 | J24: =SUM(J23:J23) -> 0 | K24: =SUM(K23:K23) -> 0 | L24: =I24+K24+J24 -> -10 | M24: =SUM(M23:M23) -> 0 | N24: =SUM(N23:N23) -> 0 | O24: =L24+N24+M24 -> -10
B25: Total-C | C25: =SUM(C23:C24) -> -10 | D25: =SUM(D23:D24) -> 0 | E25: =SUM(E23:E24) -> 0 | F25: =SUM(F23:F24) -> -10 | G25: =SUM(G23:G24) -> 0 | H25: =SUM(H23:H24) -> 0 | I25: =SUM(I23:I24) -> -10 | J25: =SUM(J23:J24) -> 0 | ... O25: =SUM(O23:O24) -> -10
B26: Net Loans - (A+B+C) | C26: =C21+C12+C25 -> 599 | D26: =D21+D12+D25 -> -57.168675 | E26: =E21+E12+E25 -> 128 | F26: =F21+F12+F25 -> 669.83133 | G26: =G21+G12+G25 -> -75.160933 | H26: =H21+H12+H25 -> 0 | I26: =I21+I12+I25 -> 594.67039 | J26: =J21+J12+J25 -> -53.344475 | ... O26: =O21+O12+O25 -> 554.15724
B28: Table linked from Working capital sheet
B29: Total Loans as on 15th August 2026
B30: Bank | C30: STL | D30: LTL | E30: Total Loan
B31: Dukhan Bank | C31: =+C7 -> 10 | D31: =+C17+C19 -> 217 | E31: =SUM(C31:D31) -> 227
B32: Mashreq Al Islami | C32: =+C8 -> 70 | D32: =+C15+C14 -> 217 | E32: =SUM(C32:D32) -> 287
B33: UBS | C33: =+C9 -> 25 | D33: =+C16 -> 60 | E33: =SUM(C33:D33) -> 85
B34: Al Rayan | C34: =+C10 -> 10 | D34: 0 | E34: =SUM(C34:D34) -> 10
B35: Total Loan | C35: =SUM(C31:C34) -> 115 | D35: =SUM(D31:D34) -> 494 | E35: =SUM(E31:E34) -> 609
B42: QDB - WC Financing (in QAR Mn)
B43: Business unit | C43: Raw Material (RM) Loan approved | D43: OPEX Loan
D44: Applied for | E44: Approval expected
B45: QFM | C45: 20 | D45: 1.5 | E45: =+D45 -> 1.5
B46: QFI | C46: 10 | D46: 2 | E46: =+D46 -> 2
B47: USB | C47: 10 | D47: =+D46+0.5 -> 2.5 | E47: =+D47 -> 2.5
B48: UNB | C48: 0 | D48: =+D47+0.5 -> 3 | E48: =+D48 -> 3
B49: ASP | C49: 0 | D49: =+D48+0.5 -> 3.5 | E49: =+D49 -> 3.5
...

Sheet 7. Cash flow unit wise detailed

Sheet HSBC - CAD
A2: CLOSING BALANCE | B2: =+K7 -> 6400
K5: CB
A6: Trade date | B6: Settlement date | C6: Description | D6: Account name | E6: Account number | F6: Portfolio name | G6: Portfolio number | H6: Transaction type | I6: Amount | J6: Amount currency | K6: 5150
A7: 46177 | B7: 46177 | D7: ZAD HOLDING COMPANY | E7: 509B222082E | F7: STANDARD | G7: 509C150664R | H7: Security Event Transaction | I7: 1250 | J7: CAD | K7: =+K6+I7 -> 6400

Sheet HSBC - USD
A2: CLOSING BALANCE | B2: =+H7 -> 4060
H5: CB
A6: Trade date | B6: Settlement date | C6: Description | D6: Portfolio number | E6: Transaction type | F6: Amount | G6: Amount currency | H6: 1560
A7: 46204 | B7: 46205 | D7: 509C150664R | E7: Money Transfer | F7: 2500 | G7: USD | H7: =+H6+F7 -> 4060
E10: =6000000/3.65 -> 1643835.6

Sheet UBS - CAD
A2: CLOSING BALANCE | B2: =+G12 -> 2800
A6: UBS Switzerland AG PO Box, CH-8098 Zurich www.ubs.com For all your questions: ubs.com/help
A7: ZAD Holding Company (Q.P.S.C.) Building 393 Al Meena Street 200 QA-Doha Zone 19
A8: UBS Business Current Account CAD 1000.00 IBAN CH67 0030 8308 2129 2661 C Current balance BIC UBSWCHZH80A
A9: Created on 08.07.2026
A10: Account transactions Filter criteria Booking amount: All Time period: 01.06.2026 - 30.06.2026
B11: Trade date Booking date | C11: Description | D11: Debit | E11: Credit | F11: Value date | G11: Balance
C12: Closing balance | G12: =+G13 -> 2800
B13: 46163 | E13: 1000 | F13: 46177 | G13: 2800

Sheet UBS - USD
A2: CLOSING BALANCE | B2: =+G11 -> 5470
A6: ZAD Holding Company (Q.P.S.C.) Building 393 Al Meena Street 200 QA-Doha Zone 19
A7: UBS Business Current Account USD 500 IBAN CH72 0030 8308 2129 2660 M Current balance BIC UBSWCHZH80A
A8: Created on 04.08.2026
A9: Account transactions Filter criteria Booking amount: All Time period: 01.07.2026 - 31.07.2026
A10: Trade date Booking date | B10: Description | C10: Debit | E10: Credit | F10: Value date | G10: Balance
B11: Closing balance | G11: =+G12+C11 -> 5470
A12: 46234 | C12: -30 | F12: 46234 | G12: =+G13+C12 -> 5470
A13: 46233 | C13: -100 | F13: 46233 | G13: 5500

Sheet ZAD-0222-0168686-001-0010-000
A2: CLOSING BALANCE | B2: =+G7 -> 2877749
A6: Transaction Date | B6: Document # | C6: Description | D6: Value Date | E6: Debit | F6: Credit | G6: Balance
A7: 01-07-2026 | B7: 0 | D7: 01-07-2026 | F7: =3314540-436000-791 -> 2877749 | G7: =+F7 -> 2877749

Sheet AUTO M-100002593758
A2: CLOSING BALANCE | B2: =+G21 -> 20100
C7: Account Statement
C8: Report generated on 2026/08/25
A9: Account Information
A10: Account Number | B10: 100002593758 | D10: Customer Name : | E10: AUTOMEDIA ADVERTISING
A11: Account Type | B11: CK | D11: Currency | E11: QAR
A12: Bank Name | B12: Dukhan Bank
A13: Branch | D13: BIC | E13: BRWAQAQAXXX
A14: IBAN | B14: QA47BRWA000000000100002593758
A15: Balance Information
A16: Current Balance | B16: 20100
A17: Available Balance | B17: 20100
A18: Transaction Statement
B19: Transaction Date From Date | D19: 2026-02-01 | E19: To Date | F19: 2026-08-24
A20: Value Date | B20: Transaction Date | C20: Narrative | D20: Transaction Reference | E20: Debits | F20: Credits | G20: Ledger Balance
A21: 2026-07-07 | B21: 2026-07-07 | E21: 2000 | F21: - | G21: 20100

Sheet NFC-100000792904
A2: CLOSING BALANCE | B2: =+G21 -> 31880
C7: Account Statement
C8: Report generated on 2026/08/25
A9: Account Information
A10: Account Number | B10: 100000792904 | D10: Customer Name : | E10: NATIONAL FOOD COMPANY W.L.L
A11: Account Type | B11: CK | D11: Currency | E11: QAR
A12: Bank Name | B12: Dukhan Bank
A13: Branch | D13: BIC | E13: BRWAQAQAXXX
A14: IBAN | B14: QA12BRWA000000000100000792904
A15: Balance Information
A16: Current Balance | B16: 31880
A17: Available Balance | B17: 31880
A18: Transaction Statement
B19: Transaction Date From Date | D19: 2026-08-01 | E19: To Date | F19: 2026-08-24
A20: Value Date | B20: Transaction Date | C20: Narrative | D20: Transaction Reference | E20: Debits | F20: Credits | G20: Ledger Balance
A21: 2026-08-13 | B21: 2026-08-13 | E21: 175 | F21: - | G21: =+G22-E21 -> 31880
A22: 2026-08-11 | B22: 2026-08-11 | E22: 18500 | F22: - | G22: 32055

Sheet USB-100001870634
A2: CLOSING BALANCE | B2: =+G21 -> 21046
C7: Account Statement
C8: Report generated on 2026/08/25
A9: Account Information
A10: Account Number | B10: 100001870634 | D10: Customer Name : | E10: UMMSAID BAKERY
A11: Account Type | B11: CK | D11: Currency | E11: USD
A12: Bank Name | B12: Dukhan Bank
A13: Branch | D13: BIC | E13: BRWAQAQAXXX
A14: IBAN | B14: QA41BRWA000000000100001870634
A15: Balance Information
A16: Current Balance | B16: 21046
A17: Available Balance | B17: 21046
A18: Transaction Statement
B19: Transaction Date From Date | D19: 2026-08-01 | E19: To Date | F19: 2026-08-24
A20: Value Date | B20: Transaction Date | C20: Narrative | D20: Transaction Reference | E20: Debits | F20: Credits | G20: Ledger Balance
A21: 2026-08-16 | B21: 2026-08-16 | E21: 30 | F21: - | G21: 21046

Sheet USB-100001870621
A2: CLOSING BALANCE | B2: =+G21 -> 65404
C7: Account Statement
C8: Report generated on 2026/08/25
A9: Account Information
A10: Account Number | B10: 100001870621 | D10: Customer Name : | E10: UMMSAID BAKERY
A11: Account Type | B11: CK | D11: Currency | E11: EUR
A12: Bank Name | B12: Dukhan Bank
A13: Branch | D13: BIC | E13: BRWAQAQAXXX
A14: IBAN | B14: QA04BRWA000000000100001870621
A15: Balance Information
A16: Current Balance | B16: 65404
A17: Available Balance | B17: 65404
A18: Transaction Statement
B19: Transaction Date From Date | D19: 2026-08-01 | E19: To Date | F19: 2026-08-24
A20: Value Date | B20: Transaction Date | C20: Narrative | D20: Transaction Reference | E20: Debits | F20: Credits | G20: Ledger Balance
A21: 2026-08-17 | B21: 2026-08-17 | E21: 250 | F21: - | G21: 65404

Sheet USB-100000792506
A2: CLOSING BALANCE | B2: =+G21 -> 60221.27
C7: Account Statement
C8: Report generated on 2026/08/25
A9: Account Information
A10: Account Number | B10: 100000792506 | D10: Customer Name : | E10: UMMSAID BAKERY
A11: Account Type | B11: CK | D11: Currency | E11: QAR
A12: Bank Name | B12: Dukhan Bank
A13: Branch | D13: BIC | E13: BRWAQAQAXXX
A14: IBAN | B14: QA88BRWA000000000100000792506
A15: Balance Information
A16: Current Balance | B16: 60221.27
A17: Available Balance | B17: 71221.27
A18: Transaction Statement
B19: Transaction Date From Date | D19: 2026-08-20 | E19: To Date | F19: 2026-08-24
A20: Value Date | B20: Transaction Date | C20: Narrative | D20: Transaction Reference | E20: Debits | F20: Credits | G20: Ledger Balance
A21: 2026-08-24 | B21: 2026-08-24 | E21: - | F21: 13709.27 | G21: 60221.27

Sheet ALC-100000841415
A2: CLOSING BALANCE | B2: =+G21 -> 51254
C7: Account Statement
C8: Report generated on 2026/08/25
A9: Account Information
A10: Account Number | B10: 100000841415 | D10: Customer Name : | E10: ALCAT LOGISTICS SERVICES AND TRADERS WLL
A11: Account Type | B11: CK | D11: Currency | E11: QAR
A12: Bank Name | B12: Dukhan Bank
A13: Branch | D13: BIC | E13: BRWAQAQAXXX
A14: IBAN | B14: QA06BRWA000000000100000841415
A15: Balance Information
A16: Current Balance | B16: 51254
A17: Available Balance | B17: 51254
A18: Transaction Statement
B19: Transaction Date From Date | D19: 2026-08-20 | E19: To Date | F19: 2026-08-24
A20: Value Date | B20: Transaction Date | C20: Narrative | D20: Transaction Reference | E20: Debits | F20: Credits | G20: Ledger Balance
A21: 2026-08-24 | B21: 2026-08-24 | E21: 4613.36 | F21: - | G21: 51254

Sheet ASP-100001845559
A2: CLOSING BALANCE | B2: =+G21 -> 26451
C7: Account Statement
C8: Report generated on 2026/08/25
A9: Account Information
A10: Account Number | B10: 100001845559 | D10: Customer Name : | E10: ALCAT ASPHALT PLANT
A11: Account Type | B11: CK | D11: Currency | E11: QAR
A12: Bank Name | B12: Dukhan Bank
A13: Branch | D13: BIC | E13: BRWAQAQAXXX
A14: IBAN | B14: QA06BRWA000000000100001845559
A15: Balance Information
A16: Current Balance | B16: 26451
A17: Available Balance | B17: 26451
A18: Transaction Statement
B19: Transaction Date From Date | D19: 2026-08-20 | E19: To Date | F19: 2026-08-24
A20: Value Date | B20: Transaction Date | C20: Narrative | D20: Transaction Reference | E20: Debits | F20: Credits | G20: Ledger Balance
A21: 2026-08-24 | B21: 2026-08-24 | E21: - | F21: 25412 | G21: 26451

Sheet AMC-100001872603
A2: CLOSING BALANCE | B2: =+G21 -> 14215
C7: Account Statement
C8: Report generated on 2026/08/25
A9: Account Information
A10: Account Number | B10: 100001872603 | D10: Customer Name : | E10: ARZAK MARKETING
A11: Account Type | B11: CK | D11: Currency | E11: USD
A12: Bank Name | B12: Dukhan Bank
A13: Branch | D13: BIC | E13: BRWAQAQAXXX
A14: IBAN | B14: QA34BRWA000000000100001872603
A15: Balance Information
A16: Current Balance | B16: 14215
A17: Available Balance | B17: 14215
A18: Transaction Statement
B19: Transaction Date From Date | D19: 2026-08-01 | E19: To Date | F19: 2026-08-24
A20: Value Date | B20: Transaction Date | C20: Narrative | D20: Transaction Reference | E20: Debits | F20: Credits | G20: Ledger Balance
A21: 2026-08-24 | B21: 2026-08-24 | E21: 150 | F21: - | G21: 14215

Sheet AMC-100000819104
A2: CLOSING BALANCE | B2: =+G21 -> 16388
C7: Account Statement
C8: Report generated on 2026/08/25
A9: Account Information
A10: Account Number | B10: 100000819104 | D10: Customer Name : | E10: ARZAK MARKETING
A11: Account Type | B11: CK | D11: Currency | E11: QAR
A12: Bank Name | B12: Dukhan Bank
A13: Branch | D13: BIC | E13: BRWAQAQAXXX
A14: IBAN | B14: QA33BRWA000000000100000819104
A15: Balance Information
A16: Current Balance | B16: 16388
A17: Available Balance | B17: 66653
A18: Transaction Statement
B19: Transaction Date From Date | D19: 2026-08-01 | E19: To Date | F19: 2026-08-24
A20: Value Date | B20: Transaction Date | C20: Narrative | D20: Transaction Reference | E20: Debits | F20: Credits | G20: Ledger Balance
A21: 2026-08-20 | B21: 2026-08-20 | E21: 156 | F21: - | G21: =+G22-E21 -> 16388
A22: 2026-08-20 | B22: 2026-08-20 | E22: 16544 | F22: - | G22: 16544

Sheet QFT-100001870728
A2: CLOSING BALANCE | B2: =+G21 -> 76205
C7: Account Statement
C8: Report generated on 2026/08/25
A9: Account Information
A10: Account Number | B10: 100001870728 | D10: Customer Name : | E10: Qatar Flour Mills Company
A11: Account Type | B11: CK | D11: Currency | E11: USD
A12: Bank Name | B12: Dukhan Bank
A13: Branch | D13: BIC | E13: BRWAQAQAXXX
A14: IBAN | B14: QA25BRWA000000000100001870728
A15: Balance Information
A16: Current Balance | B16: 76205
A17: Available Balance | B17: 76205
A18: Transaction Statement
B19: Transaction Date From Date | D19: 2026-08-01 | E19: To Date | F19: 2026-08-24
A20: Value Date | B20: Transaction Date | C20: Narrative | D20: Transaction Reference | E20: Debits | F20: Credits | G20: Ledger Balance
A21: 2026-08-19 | B21: 2026-08-19 | E21: 30 | F21: - | G21: =+G22-E21 -> 76205
A22: 2026-08-19 | B22: 2026-08-19 | E22: 46841 | F22: - | G22: 76235

Sheet QFM-1000001870702
A2: CLOSING BALANCE | B2: =+G21 -> 11546
C7: Account Statement
C8: Report generated on 2026/08/25
A9: Account Information
A10: Account Number | B10: 100001870702 | D10: Customer Name : | E10: Qatar Flour Mills Company
A11: Account Type | B11: CK | D11: Currency | E11: CHF
A12: Bank Name | B12: Dukhan Bank
A13: Branch | D13: BIC | E13: BRWAQAQAXXX
A14: IBAN | B14: QA48BRWA000000000100001870702
A15: Balance Information
A16: Current Balance | B16: 11546
A17: Available Balance | B17: 11546
A18: Transaction Statement
B19: Transaction Date From Date | D19: 2026-08-20 | E19: To Date | F19: 2026-08-24
A20: Value Date | B20: Transaction Date | C20: Narrative | D20: Transaction Reference | E20: Debits | F20: Credits | G20: Ledger Balance
A21: 2026-08-20 | B21: 2026-08-20 | E21: - | F21: 7898 | G21: 11546

Sheet QFM-100001870618
A2: CLOSING BALANCE | B2: =+G21 -> 54684.56
C7: Account Statement
C8: Report generated on 2026/08/25
A9: Account Information
A10: Account Number | B10: 100001870618 | D10: Customer Name : | E10: Qatar Flour Mills Company
A11: Account Type | B11: CK | D11: Currency | E11: USD
A12: Bank Name | B12: Dukhan Bank
A13: Branch | D13: BIC | E13: BRWAQAQAXXX
A14: IBAN | B14: QA85BRWA000000000100001870618
A15: Balance Information
A16: Current Balance | B16: 54684.56
A17: Available Balance | B17: 54684.56
A18: Transaction Statement
B19: Transaction Date From Date | D19: 2026-08-20 | E19: To Date | F19: 2026-08-24
A20: Value Date | B20: Transaction Date | C20: Narrative | D20: Transaction Reference | E20: Debits | F20: Credits | G20: Ledger Balance
A21: 2026-08-20 | B21: 2026-08-20 | E21: 95 | F21: - | G21: =+G22-E21 -> 54684.56
A22: 2026-08-20 | B22: 2026-08-20 | E22: 264672.84 | F22: - | G22: 54779.56

Sheet QFM-100000832880
A2: CLOSING BALANCE | B2: =+G21 -> 25182
C7: Account Statement
C8: Report generated on 2026/08/25
A9: Account Information
A10: Account Number | B10: 100000832880 | D10: Customer Name : | E10: Qatar Flour Mills Company
A11: Account Type | B11: CK | D11: Currency | E11: QAR
A12: Bank Name | B12: Dukhan Bank
A13: Branch | D13: BIC | E13: BRWAQAQAXXX
A14: IBAN | B14: QA76BRWA000000000100000832880
A15: Balance Information
A16: Current Balance | B16: 25182
A17: Available Balance | B17: 68587.56
A18: Transaction Statement
B19: Transaction Date From Date | D19: 2026-08-20 | E19: To Date | F19: 2026-08-24
A20: Value Date | B20: Transaction Date | C20: Narrative | D20: Transaction Reference | E20: Debits | F20: Credits | G20: Ledger Balance
A21: 2026-08-24 | B21: 2026-08-24 | E21: - | F21: 9542 | G21: =+G22+F21 -> 25182
A22: 2026-08-24 | B22: 2026-08-24 | E22: 5064 | F22: - | G22: 15640

Sheet QFT-100000185812
A2: CLOSING BALANCE | B2: =+G21 -> 8051
C7: Account Statement
C8: Report generated on 2026/08/25
A9: Account Information
A10: Account Number | B10: 100000185812 | D10: Customer Name : | E10: Qatar Flour Mills Company
A11: Account Type | B11: CK | D11: Currency | E11: QAR
A12: Bank Name | B12: Dukhan Bank
A13: Branch | D13: BIC | E13: BRWAQAQAXXX
A14: IBAN | B14: QA48BRWA000000000100000185812
A15: Balance Information
A16: Current Balance | B16: 8051
A17: Available Balance | B17: 96594
A18: Transaction Statement
B19: Transaction Date From Date | D19: 2026-08-20 | E19: To Date | F19: 2026-08-24
A20: Value Date | B20: Transaction Date | C20: Narrative | D20: Transaction Reference | E20: Debits | F20: Credits | G20: Ledger Balance
A21: 2026-08-24 | B21: 2026-08-24 | F21: 2625 | G21: =+G22+F21 -> 8051
A22: 2026-08-24 | B22: 2026-08-24 | E22: 2625 | G22: 5426

Sheet ZAD-200001066225
A2: CLOSING BALANCE | B2: =+G21 -> 31866
C7: Account Statement
C8: Report generated on 2026/08/25
A9: Account Information
A10: Account Number | B10: 200001066225 | D10: Customer Name : | E10: Zad Holding Company
A11: Account Type | B11: SV | D11: Currency | E11: QAR
A12: Bank Name | B12: Dukhan Bank
A13: Branch | D13: BIC | E13: BRWAQAQAXXX
A14: IBAN | B14: QA67BRWA000000000200001066225
A15: Balance Information
A16: Current Balance | B16: 31866
A17: Available Balance | B17: 31866
A18: Transaction Statement
B19: Transaction Date From Date | D19: 2026-08-20 | E19: To Date | F19: 2026-08-24
A20: Value Date | B20: Transaction Date | C20: Narrative | D20: Transaction Reference | E20: Debits | F20: Credits | G20: Ledger Balance
A21: 2026-08-24 | B21: 2026-08-24 | E21: 32458 | F21: - | G21: =+G22-E21 -> 31866
A22: 2026-08-24 | B22: 2026-08-24 | E22: 9546 | F22: - | G22: 64324

Sheet ZAD-200000597452
A2: CLOSING BALANCE | B2: =+G21 -> 261842
C7: Account Statement
C8: Report generated on 2026/08/25
A9: Account Information
A10: Account Number | B10: 200000597452 | D10: Customer Name : | E10: Zad Holding Company
A11: Account Type | B11: SV | D11: Currency | E11: QAR
A12: Bank Name | B12: Dukhan Bank
A13: Branch | D13: BIC | E13: BRWAQAQAXXX
A14: IBAN | B14: QA87BRWA000000000200000597452
A15: Balance Information
A16: Current Balance | B16: 261842
A17: Available Balance | B17: 261842
A18: Transaction Statement
B19: Transaction Date From Date | D19: 2026-08-20 | E19: To Date | F19: 2026-08-24
A20: Value Date | B20: Transaction Date | C20: Narrative | D20: Transaction Reference | E20: Debits | F20: Credits | G20: Ledger Balance
A21: 2026-08-24 | B21: 2026-08-24 | E21: 1610 | F21: - | G21: =+G22-E21 -> 261842
A22: 2026-08-24 | B22: 2026-08-24 | E22: 62458 | F22: - | G22: 263452

Sheet ZAD-1000002781078
A2: CLOSING BALANCE | B2: =+G21 -> 56564
C7: Account Statement
C8: Report generated on 2026/08/25
A9: Account Information
A10: Account Number | B10: 100002781078 | D10: Customer Name : | E10: Zad Holding Company
A11: Account Type | B11: CK | D11: Currency | E11: CHF
A12: Bank Name | B12: Dukhan Bank
A13: Branch | D13: BIC | E13: BRWAQAQAXXX
A14: IBAN | B14: QA84BRWA000000000100002781078
A15: Balance Information
A16: Current Balance | B16: 56564
A17: Available Balance | B17: 56564
A18: Transaction Statement
B19: Transaction Date From Date | D19: 2026-08-20 | E19: To Date | F19: 2026-08-24
A20: Value Date | B20: Transaction Date | C20: Narrative | D20: Transaction Reference | E20: Debits | F20: Credits | G20: Ledger Balance
A21: 2026-08-20 | B21: 2026-08-20 | E21: 46554 | F21: - | G21: 56564

Sheet ZAD-100000484005
A2: CLOSING BALANCE | B2: =+G21 -> 65396
C7: Account Statement
C8: Report generated on 2026/08/25
A9: Account Information
A10: Account Number | B10: 100000484005 | D10: Customer Name : | E10: Zad Holding Company
A11: Account Type | B11: CK | D11: Currency | E11: USD
A12: Bank Name | B12: Dukhan Bank
A13: Branch | D13: BIC | E13: BRWAQAQAXXX
A14: IBAN | B14: QA31BRWA000000000100000484005
A15: Balance Information
A16: Current Balance | B16: 65396
A17: Available Balance | B17: 65396
A18: Transaction Statement
B19: Transaction Date From Date | D19: 2026-08-20 | E19: To Date | F19: 2026-08-24
A20: Value Date | B20: Transaction Date | C20: Narrative | D20: Transaction Reference | E20: Debits | F20: Credits | G20: Ledger Balance
A21: 2026-08-23 | B21: 2026-08-23 | E21: 29 | F21: - | G21: =+G22-E21 -> 65396
A22: 2026-08-23 | B22: 2026-08-23 | E22: 4642 | F22: - | G22: 65425

Sheet ZAD-100000182792
A2: CLOSING BALANCE | B2: =+G21 -> 58917
C7: Account Statement
C8: Report generated on 2026/08/25
A9: Account Information
A10: Account Number | B10: 100000182792 | D10: Customer Name : | E10: Zad Holding Company
A11: Account Type | B11: CK | D11: Currency | E11: QAR
A12: Bank Name | B12: Dukhan Bank
A13: Branch | D13: BIC | E13: BRWAQAQAXXX
A14: IBAN | B14: QA11BRWA000000000100000182792
A15: Balance Information
A16: Current Balance | B16: 58917
A17: Available Balance | B17: 163564
A18: Transaction Statement
B19: Transaction Date From Date | D19: 2026-08-22 | E19: To Date | F19: 2026-08-24
A20: Value Date | B20: Transaction Date | C20: Narrative | D20: Transaction Reference | E20: Debits | F20: Credits | G20: Ledger Balance
A21: 2026-08-24 | B21: 2026-08-24 | E21: 545 | F21: - | G21: =+G22-E21 -> 58917
A22: 2026-08-24 | B22: 2026-08-24 | E22: - | F22: 9465 | G22: 59462

Sheet ZAD-0003177700001
A2: CLOSING BALANCE | B2: =+H7 -> 408426
A6: Account Type | B6: Account Number | C6: Entity | D6: Account Name | E6: Status | F6: Account Currency | G6: Ledger Balance | H6: Available Balance | I6: Bank Name | J6: Start Date | K6: End Date
A7: Current Account | B7: 3177700001 | C7: ZAD HOLDING COMPANY | D7: QAR 0003177700001 Current Account | E7: Active | F7: QAR | G7: 408426 | H7: =+I10 -> 408426 | I7: ARB | J7: 46334 | K7: 25/08/2026
A9: Transaction Date | B9: Value Date | C9: Description | D9: Type | E9: Reference | F9: Cheque No. | G9: Deposit | H9: Withdrawal | I9: Balance
A10: 16/08/2026 12:00:21 | B10: 16/08/2026 | D10: Credit Card payment | F10: - | G10: - | H10: -150000 | I10: =+I11-H10 -> 408426
A11: 16/08/2026 11:56:24 | B11: 16/08/2026 | D11: Credit Card payment | F11: - | G11: - | H11: -134546 | I11: 258426

Sheet ZAD-0003177700004
A2: CLOSING BALANCE | B2: =+I10 -> 70800
A6: Account Type | B6: Account Number | C6: Entity | D6: Account Name | E6: Status | F6: Account Currency | G6: Ledger Balance | H6: Available Balance | I6: Bank Name | J6: Start Date | K6: End Date
A7: Current Account | B7: 3177700004 | C7: ZAD HOLDING COMPANY | D7: USD 0003177700004 Current Account | E7: Active | F7: USD | G7: 70800 | H7: =+I10 -> 70800 | I7: ARB | J7: 46029 | K7: 31/07/2026
A9: Transaction Date | B9: Value Date | C9: Description | D9: Type | E9: Reference | F9: Cheque No. | G9: Deposit | H9: Withdrawal | I9: Balance
A10: 30/07/2026 09:12:33 | B10: 30/07/2026 | D10: Debit | H10: -4654 | I10: =+I11+H10 -> 70800
A11: 23/07/2026 09:34:12 | B11: 23/07/2026 | D11: Debit | H11: -97898 | I11: 75454

Sheet ZAD-11941000032
A2: CLOSING BALANCE | B2: =+H8 -> 638733
A6: Transaction Date | B6: Transaction Description | C6: Transaction Reference | D6: Customer Reference | E6: Transaction Remarks | F6: Debit Amount | G6: Credit Amount | H6: Balance
A7: 46233 | B7: Funds Transfer | F7: 65428 | G7: 0 | H7: 645218
A8: 46233 | B8: Funds Transfer | F8: 6485 | G8: 0 | H8: =+H7-F8 -> 638733

Sheet ZAD-29000000712
A2: CLOSING BALANCE | B2: =+H7 -> 9845
A6: Transaction Date | B6: Transaction Description | C6: Transaction Reference | D6: Customer Reference | E6: Transaction Remarks | F6: Debit Amount | G6: Credit Amount | H6: Balance
A7: 46033 | F7: 650 | G7: 0 | H7: 9845

Sheet ZAD-19120001103
A2: CLOSING BALANCE | B2: =+H8 -> 6942.78
A6: Transaction Date | B6: Transaction Description | C6: Transaction Reference | D6: Customer Reference | E6: Transaction Remarks | F6: Debit Amount | G6: Credit Amount | H6: Balance
A7: 46232 | G7: 5500 | H7: 7887.78
A8: 46232 | F8: 945 | H8: =+H7-F8 -> 6942.78

Sheet ZAD-0111051730026
A2: CLOSING BALANCE | B2: =+F9 -> 34557
A7: DATE | B7: REFERENCE_NO | C7: CURRENCY | D7: DEBIT AMOUNT | E7: CREDIT AMOUNT | F7: BALANCE | G7: ACCOUNT_NUMBER | H7: DESCRIPTION
A8: 01-07-2026 | C8: QAR | D8: 50 | F8: 34621 | G8: 0111051730026
A9: 01-07-2026 | C9: QAR | D9: 64 | F9: =+F8-D9 -> 34557 | G9: 0111051730026

Sheet QFI-100001870692
A2: CLOSING BALANCE | B2: =+G21 -> 63791
C7: Account Statement
C8: Report generated on 2026/08/25
A9: Account Information
A10: Account Number | B10: 100001870692 | D10: Customer Name : | E10: QATAR FOOD INDUSTRIES CO (FOODCO)
A11: Account Type | B11: CK | D11: Currency | E11: USD
A12: Bank Name | B12: Dukhan Bank
A13: Branch | D13: BIC | E13: BRWAQAQAXXX
A14: IBAN | B14: QA27BRWA000000000100001870692
A15: Balance Information
A16: Current Balance | B16: 63791
A17: Available Balance | B17: 63791
A18: Transaction Statement
B19: Transaction Date From Date | D19: 2026-08-20 | E19: To Date | F19: 2026-08-24
A20: Value Date | B20: Transaction Date | C20: Narrative | D20: Transaction Reference | E20: Debits | F20: Credits | G20: Ledger Balance
A21: 2026-08-24 | B21: 2026-08-24 | F21: 15140 | G21: =+G22+F21 -> 63791
A22: 2026-08-24 | B22: 2026-08-24 | E22: 6545 | F22: - | G22: 48651

Sheet QFI-100001870689
A2: CLOSING BALANCE | B2: =+G21 -> 5981
C7: Account Statement
C8: Report generated on 2026/08/25
A9: Account Information
A10: Account Number | B10: 100001870689 | D10: Customer Name : | E10: QATAR FOOD INDUSTRIES CO (FOODCO)
A11: Account Type | B11: CK | D11: Currency | E11: EUR
A12: Bank Name | B12: Dukhan Bank
A13: Branch | D13: BIC | E13: BRWAQAQAXXX
A14: IBAN | B14: QA11BRWA000000000100001870689
A15: Balance Information
A16: Current Balance | B16: 5981
A17: Available Balance | B17: 5981
A18: Transaction Statement
B19: Transaction Date From Date | D19: 2026-08-01 | E19: To Date | F19: 2026-08-24
A20: Value Date | B20: Transaction Date | C20: Narrative | D20: Transaction Reference | E20: Debits | F20: Credits | G20: Ledger Balance
A21: 2026-08-19 | B21: 2026-08-19 | E21: 4564 | F21: - | G21: =+G22-E21 -> 5981
A22: 2026-08-12 | B22: 2026-08-12 | E22: - | F22: 25 | G22: 10545

Sheet QFI-100000832877
A2: CLOSING BALANCE | B2: =+G21 -> 45854
C7: Account Statement
C8: Report generated on 2026/08/25
A9: Account Information
A10: Account Number | B10: 100000832877 | D10: Customer Name : | E10: QATAR FOOD INDUSTRIES CO (FOODCO)
A11: Account Type | B11: CK | D11: Currency | E11: QAR
A12: Bank Name | B12: Dukhan Bank
A13: Branch | D13: BIC | E13: BRWAQAQAXXX
A14: IBAN | B14: QA60BRWA000000000100000832877
A15: Balance Information
A16: Current Balance | B16: 45854
A17: Available Balance | B17: 164865
A18: Transaction Statement
B19: Transaction Date From Date | D19: 2026-08-01 | E19: To Date | F19: 2026-08-24
A20: Value Date | B20: Transaction Date | C20: Narrative | D20: Transaction Reference | E20: Debits | F20: Credits | G20: Ledger Balance
A21: 2026-08-13 | B21: 2026-08-13 | E21: 25 | F21: - | G21: =+G22-E21 -> 45854
A22: 2026-08-12 | B22: 2026-08-12 | E22: 2354 | F22: - | G22: 45879

Sheet QFI-100000780301
A2: CLOSING BALANCE | B2: =+G21 -> 90531
C7: Account Statement
C8: Report generated on 2026/08/25
A9: Account Information
A10: Account Number | B10: 100000780301 | D10: Customer Name : | E10: QATAR FOOD INDUSTRIES CO (FOODCO)
A11: Account Type | B11: CK | D11: Currency | E11: QAR
A12: Bank Name | B12: Dukhan Bank
A13: Branch | D13: BIC | E13: BRWAQAQAXXX
A14: IBAN | B14: QA17BRWA000000000100000780301
A15: Balance Information
A16: Current Balance | B16: 90531
A17: Available Balance | B17: 254862
A18: Transaction Statement
B19: Transaction Date From Date | D19: 2026-08-20 | E19: To Date | F19: 2026-08-24
A20: Value Date | B20: Transaction Date | C20: Narrative | D20: Transaction Reference | E20: Debits | F20: Credits | G20: Ledger Balance
A21: 2026-08-24 | B21: 2026-08-24 | E21: - | F21: 1080 | G21: =+G22+F21 -> 90531
A22: 2026-08-24 | B22: 2026-08-24 | E22: - | F22: 11153 | G22: 89451

Sheet UNB-100001798347
A2: CLOSING BALANCE | B2: =+G21 -> 73391
C7: Account Statement
C8: Report generated on 2026/08/25
A9: Account Information
A10: Account Number | B10: 100001798347 | D10: Customer Name : | E10: UNITED BAKERIES
A11: Account Type | B11: CK | D11: Currency | E11: QAR
A12: Bank Name | B12: Dukhan Bank
A13: Branch | D13: BIC | E13: BRWAQAQAXXX
A14: IBAN | B14: QA53BRWA000000000100001798347
A15: Balance Information
A16: Current Balance | B16: 73391
A17: Available Balance | B17: 854588
A18: Transaction Statement
B19: Transaction Date From Date | D19: 2026-08-22 | E19: To Date | F19: 2026-08-24
A20: Value Date | B20: Transaction Date | C20: Narrative | D20: Transaction Reference | E20: Debits | F20: Credits | G20: Ledger Balance
A21: 2026-08-24 | B21: 2026-08-24 | E21: 74454 | G21: =+G22-E21 -> 73391
A22: 2026-08-24 | B22: 2026-08-24 | E22: - | F22: 14754 | G22: 147845

Sheet ACC-100001870650
A2: CLOSING BALANCE | B2: =+G21 -> 5624
C7: Account Statement
C8: Report generated on 2026/08/25
A9: Account Information
A10: Account Number | B10: 100001870650 | D10: Customer Name : | E10: ALCAT CONTRACTING
A11: Account Type | B11: CK | D11: Currency | E11: USD
A12: Bank Name | B12: Dukhan Bank
A13: Branch | D13: BIC | E13: BRWAQAQAXXX
A14: IBAN | B14: QA94BRWA000000000100001870650
A15: Balance Information
A16: Current Balance | B16: 5624
A17: Available Balance | B17: 5624
A18: Transaction Statement
B19: Transaction Date From Date | D19: 2026-08-01 | E19: To Date | F19: 2026-08-24
A20: Value Date | B20: Transaction Date | C20: Narrative | D20: Transaction Reference | E20: Debits | F20: Credits | G20: Ledger Balance
A21: 2026-08-16 | B21: 2026-08-16 | E21: 30 | F21: - | G21: =+G22-E21 -> 5624
A22: 2026-08-16 | B22: 2026-08-16 | E22: 445 | F22: - | G22: 5654

Sheet ACC-100000827646
A2: CLOSING BALANCE | B2: =+G21 -> 6484
C7: Account Statement
C8: Report generated on 2026/08/25
A9: Account Information
A10: Account Number | B10: 100000827646 | D10: Customer Name : | E10: ALCAT CONTRACTING
A11: Account Type | B11: CK | D11: Currency | E11: QAR
A12: Bank Name | B12: Dukhan Bank
A13: Branch | D13: BIC | E13: BRWAQAQAXXX
A14: IBAN | B14: QA65BRWA000000000100000827646
A15: Balance Information
A16: Current Balance | B16: 6484
A17: Available Balance | B17: 92245.36
A18: Transaction Statement
B19: Transaction Date From Date | D19: 2026-08-01 | E19: To Date | F19: 2026-08-24
A20: Value Date | B20: Transaction Date | C20: Narrative | D20: Transaction Reference | E20: Debits | F20: Credits | G20: Ledger Balance
A21: 2026-08-13 | B21: 2026-08-13 | E21: 25 | F21: - | G21: 6484

Sheet ACC-100000279773
A2: CLOSING BALANCE | B2: =+G21 -> 16031
C7: Account Statement
C8: Report generated on 2026/08/25
A9: Account Information
A10: Account Number | B10: 100000279773 | D10: Customer Name : | E10: ALCAT CONTRACTING
A11: Account Type | B11: CK | D11: Currency | E11: QAR
A12: Bank Name | B12: Dukhan Bank
A13: Branch | D13: BIC | E13: BRWAQAQAXXX
A14: IBAN | B14: QA39BRWA000000000100000279773
A15: Balance Information
A16: Current Balance | B16: 16031
A17: Available Balance | B17: 65144.89
A18: Transaction Statement
B19: Transaction Date From Date | D19: 2026-08-22 | E19: To Date | F19: 2026-08-24
A20: Value Date | B20: Transaction Date | C20: Narrative | D20: Transaction Reference | E20: Debits | F20: Credits | G20: Ledger Balance
A21: 2026-08-24 | B21: 2026-08-24 | E21: 9458 | F21: - | G21: =+G22-E21 -> 16031
A22: 2026-08-23 | B22: 2026-08-23 | E22: 1574 | F22: - | G22: 25489

Sheet ACC-100001870647
A2: CLOSING BALANCE | B2: =+G21 -> 991
C7: Account Statement
C8: Report generated on 2026/08/25
A9: Account Information
A10: Account Number | B10: 100001870647 | D10: Customer Name : | E10: ALCAT CONTRACTING
A11: Account Type | B11: CK | D11: Currency | E11: EUR
A12: Bank Name | B12: Dukhan Bank
A13: Branch | D13: BIC | E13: BRWAQAQAXXX
A14: IBAN | B14: QA78BRWA000000000100001870647
A15: Balance Information
A16: Current Balance | B16: 991
A17: Available Balance | B17: 991
A18: Transaction Statement
B19: Transaction Date From Date | D19: 2026-07-01 | E19: To Date | F19: 2026-08-24
A20: Value Date | B20: Transaction Date | C20: Narrative | D20: Transaction Reference | E20: Debits | F20: Credits | G20: Ledger Balance
A21: 2026-08-02 | B21: 2026-07-31 | E21: 24 | F21: - | G21: =+G22-E21 -> 991
A22: 2026-07-01 | B22: 2026-06-30 | E22: 24 | F22: - | G22: 1015

Sheet GUC-100000824416
A2: CLOSING BALANCE | B2: =+G21 -> 23549
C7: Account Statement
C8: Report generated on 2026/08/25
A9: Account Information
A10: Account Number | B10: 100000824416 | D10: Customer Name : | E10: GULF UNITED REAL ESTATE INVESTMANT
A11: Account Type | B11: CK | D11: Currency | E11: QAR
A12: Bank Name | B12: Dukhan Bank
A13: Branch | D13: BIC | E13: BRWAQAQAXXX
A14: IBAN | B14: QA72BRWA000000000100000824416
A15: Balance Information
A16: Current Balance | B16: 23549
A17: Available Balance | B17: 96458
A18: Transaction Statement
B19: Transaction Date From Date | D19: 2026-08-22 | E19: To Date | F19: 2026-08-24
A20: Value Date | B20: Transaction Date | C20: Narrative | D20: Transaction Reference | E20: Debits | F20: Credits | G20: Ledger Balance
A21: 2026-08-24 | B21: 2026-08-24 | E21: - | F21: 13000 | G21: =+G22+F21 -> 23549
A22: 2026-08-24 | B22: 2026-08-24 | E22: 2500 | F22: - | G22: 10549
